I'm sorry, but an uncaught exception occurred.

While running game code:
  File "game/script.rpy", line 10, in script
    pov "Is this a locker room?"
KeyError: "'name'"

-- Full Traceback ------------------------------------------------------------

Full traceback:
  File "game/script.rpy", line 10, in script
    pov "Is this a locker room?"
  File "/Users/akpulaski/Applications/renpy-8.1.0-sdk/renpy/ast.py", line 930, in execute
    renpy.exports.say(who, what, *args, **kwargs)
  File "/Users/akpulaski/Applications/renpy-8.1.0-sdk/renpy/exports.py", line 1473, in say
    who(what, *args, **kwargs)
  File "/Users/akpulaski/Applications/renpy-8.1.0-sdk/renpy/character.py", line 1335, in __call__
    who = self.prefix_suffix("who", self.who_prefix, who, self.who_suffix)
  File "/Users/akpulaski/Applications/renpy-8.1.0-sdk/renpy/character.py", line 1251, in prefix_suffix
    return (sub(prefix) + sub(body) + sub(suffix))
  File "/Users/akpulaski/Applications/renpy-8.1.0-sdk/renpy/character.py", line 1231, in sub
    return renpy.substitutions.substitute(s, scope=scope, force=force, translate=translate)[0]
  File "/Users/akpulaski/Applications/renpy-8.1.0-sdk/renpy/substitutions.py", line 278, in substitute
    s = formatter.vformat(s, (), kwargs) # type: ignore
  File "/home/tom/ab/renpy-build/tmp/install.linux-x86_64/lib/python3.9/string.py", line 165, in vformat
  File "/home/tom/ab/renpy-build/tmp/install.linux-x86_64/lib/python3.9/string.py", line 205, in _vformat
  File "/Users/akpulaski/Applications/renpy-8.1.0-sdk/renpy/substitutions.py", line 168, in get_field
    obj, arg_used = super(Formatter, self).get_field(field_name, args, kwargs)
  File "/home/tom/ab/renpy-build/tmp/install.linux-x86_64/lib/python3.9/string.py", line 270, in get_field
  File "/home/tom/ab/renpy-build/tmp/install.linux-x86_64/lib/python3.9/string.py", line 227, in get_value
KeyError: "'name'"

macOS-13.4.1-arm64-arm-64bit arm64
Ren'Py 8.1.1.23060707
Dreadfield Stadium 1.0
Sun Jul 23 15:04:28 2023
